<?xml version="1.0" ?>
<!-- =================================================================================== -->
<!-- |    This document was autogenerated by xacro from src/gpu_slam_bot/urdf/gpu_slam_bot.urdf.xacro | -->
<!-- |    EDITING THIS FILE BY HAND IS NOT RECOMMENDED                                 | -->
<!-- =================================================================================== -->
<robot name="gpu_slam_bot">
  <!-- Materials -->
  <material name="metallic_gray">
    <color rgba="0.7 0.7 0.75 1"/>
  </material>
  <material name="wheel_black">
    <color rgba="0 0 0 1"/>
  </material>
  <material name="stripe_green">
    <color rgba="0 1 0 1"/>
  </material>
  <material name="pusher_red">
    <color rgba="1 0 0 1"/>
  </material>
  <!-- Base link -->
  <link name="base_link">
    <visual>
      <origin rpy="0 0 0" xyz="0 0 0"/>
      <geometry>
        <cylinder length="0.08" radius="0.225"/>
      </geometry>
      <material name="metallic_gray"/>
    </visual>
    <collision>
      <origin rpy="0 0 0" xyz="0 0 0"/>
      <geometry>
        <cylinder length="0.08" radius="0.225"/>
      </geometry>
    </collision>
    <inertial>
      <origin xyz="0 0 0"/>
      <mass value="3.0"/>
      <inertia ixx="0.03956875" ixy="0" ixz="0" iyy="0.03956875" iyz="0" izz="0.0759375"/>
    </inertial>
  </link>
  <!-- Wheels -->
  <link name="wheel_left">
    <visual>
      <origin rpy="1.5708 0 0" xyz="0 0 0"/>
      <geometry>
        <cylinder length="0.06" radius="0.08"/>
      </geometry>
      <material name="wheel_black"/>
    </visual>
    <collision>
      <origin rpy="1.5708 0 0" xyz="0 0 0"/>
      <geometry>
        <cylinder length="0.06" radius="0.08"/>
      </geometry>
    </collision>
    <inertial>
      <origin xyz="0 0 0"/>
      <mass value="1.5"/>
      <inertia ixx="0.0028499999999999997" ixy="0" ixz="0" iyy="0.0048" iyz="0" izz="0.0028499999999999997"/>
    </inertial>
  </link>
  <link name="wheel_right">
    <visual>
      <origin rpy="1.5708 0 0" xyz="0 0 0"/>
      <geometry>
        <cylinder length="0.06" radius="0.08"/>
      </geometry>
      <material name="wheel_black"/>
    </visual>
    <collision>
      <origin rpy="1.5708 0 0" xyz="0 0 0"/>
      <geometry>
        <cylinder length="0.06" radius="0.08"/>
      </geometry>
    </collision>
    <inertial>
      <origin xyz="0 0 0"/>
      <mass value="1.5"/>
      <inertia ixx="0.0028499999999999997" ixy="0" ixz="0" iyy="0.0048" iyz="0" izz="0.0028499999999999997"/>
    </inertial>
  </link>
  <joint name="wheel_left_joint" type="continuous">
    <parent link="base_link"/>
    <child link="wheel_left"/>
    <origin rpy="0 0 0" xyz="0 0.2 -0.04"/>
    <axis xyz="0 1 0"/>
    <dynamics damping="0.2" friction="0.0"/>
  </joint>
  <joint name="wheel_right_joint" type="continuous">
    <parent link="base_link"/>
    <child link="wheel_right"/>
    <origin rpy="0 0 0" xyz="0 -0.2 -0.04"/>
    <axis xyz="0 1 0"/>
    <dynamics damping="0.2" friction="0.0"/>
  </joint>
  <!-- Lifter link (shortened height from 0.2m to 0.1m) -->
  <link name="lifter_link">
    <visual>
      <geometry>
        <box size="0.05 0.05 0.1"/>
      </geometry>
      <material name="metallic_gray"/>
    </visual>
    <collision>
      <geometry>
        <box size="0.05 0.05 0.1"/>
      </geometry>
      <surface>
        <friction>
          <ode>
            <mu>0.8</mu>
            <mu2>0.8</mu2>
          </ode>
        </friction>
        <contact>
          <ode>
            <kp>1000000.0</kp>
            <kd>100.0</kd>
          </ode>
        </contact>
      </surface>
    </collision>
    <inertial>
      <mass value="0.1"/>
      <!-- Reduced from 0.2 to reflect smaller size -->
      <inertia ixx="0.00010416666666666669" ixy="0" ixz="0" iyy="0.00010416666666666669" iyz="0" izz="4.166666666666667e-05"/>
    </inertial>
  </link>
  <joint name="front_lifter_joint" type="prismatic">
    <parent link="base_link"/>
    <child link="lifter_link"/>
    <origin rpy="0 0 0" xyz="0.225 0 -0.04"/>
    <axis xyz="0 0 1"/>
    <limit effort="15" lower="0.0" upper="0.4" velocity="0.2"/>
    <!-- Increased upper limit to 0.4m -->
    <dynamics damping="0.3" friction="0.1"/>
  </joint>
  <!-- Left gripper arm -->
  <link name="left_arm_link">
    <visual>
      <origin rpy="0 1.5708 0" xyz="0.06 0 0"/>
      <geometry>
        <cylinder length="0.12" radius="0.015"/>
      </geometry>
      <material name="pusher_red"/>
    </visual>
    <collision>
      <origin rpy="0 1.5708 0" xyz="0.06 0 0"/>
      <geometry>
        <cylinder length="0.12" radius="0.015"/>
      </geometry>
      <surface>
        <friction>
          <ode>
            <mu>1.0</mu>
            <mu2>1.0</mu2>
          </ode>
        </friction>
        <contact>
          <ode>
            <kp>1000000.0</kp>
            <kd>100.0</kd>
          </ode>
        </contact>
      </surface>
    </collision>
    <inertial>
      <origin xyz="0 0 0"/>
      <mass value="0.07"/>
      <inertia ixx="7.875000000000002e-06" ixy="0" ixz="0" iyy="8.793749999999999e-05" iyz="0" izz="8.793749999999999e-05"/>
    </inertial>
  </link>
  <joint name="left_gripper_joint" type="revolute">
    <parent link="lifter_link"/>
    <child link="left_arm_link"/>
    <origin rpy="0 0 0" xyz="0 0.09 0.05"/>
    <!-- Adjusted z to 0.05m -->
    <axis xyz="0 0 1"/>
    <limit effort="20" lower="-0.6" upper="0.6" velocity="2.0"/>
    <dynamics damping="0.3" friction="0.05"/>
  </joint>
  <!-- Left tip -->
  <link name="left_tip_link">
    <visual>
      <origin rpy="0 1.5708 0" xyz="0.06 0 0"/>
      <geometry>
        <cylinder length="0.12" radius="0.015"/>
      </geometry>
      <material name="pusher_red"/>
    </visual>
    <collision>
      <origin rpy="0 1.5708 0" xyz="0.06 0 0"/>
      <geometry>
        <cylinder length="0.12" radius="0.015"/>
      </geometry>
      <surface>
        <friction>
          <ode>
            <mu>1.0</mu>
            <mu2>1.0</mu2>
          </ode>
        </friction>
        <contact>
          <ode>
            <kp>1000000.0</kp>
            <kd>100.0</kd>
          </ode>
        </contact>
      </surface>
    </collision>
    <inertial>
      <origin xyz="0 0 0"/>
      <mass value="0.07"/>
      <inertia ixx="7.875000000000002e-06" ixy="0" ixz="0" iyy="8.793749999999999e-05" iyz="0" izz="8.793749999999999e-05"/>
    </inertial>
  </link>
  <joint name="left_tip_joint" type="fixed">
    <parent link="left_arm_link"/>
    <child link="left_tip_link"/>
    <origin rpy="0 0 -0.349" xyz="0.12 0 0"/>
  </joint>
  <!-- Left tip sphere -->
  <link name="left_sphere_link">
    <visual>
      <origin rpy="0 0 0" xyz="0 0 0"/>
      <geometry>
        <sphere radius="0.02"/>
      </geometry>
      <material name="pusher_red"/>
    </visual>
    <collision name="left_sphere_link_collision">
      <origin rpy="0 0 0" xyz="0 0 0"/>
      <geometry>
        <sphere radius="0.02"/>
      </geometry>
    </collision>
    <inertial>
      <origin xyz="0 0 0"/>
      <mass value="0.02"/>
      <inertia ixx="3.2000000000000003e-06" ixy="0" ixz="0" iyy="3.2000000000000003e-06" iyz="0" izz="3.2000000000000003e-06"/>
    </inertial>
  </link>
  <joint name="left_sphere_joint" type="fixed">
    <parent link="left_tip_link"/>
    <child link="left_sphere_link"/>
    <origin rpy="0 0 0" xyz="0.12 0 0"/>
  </joint>
  <!-- Right gripper arm -->
  <link name="right_arm_link">
    <visual>
      <origin rpy="0 1.5708 0" xyz="0.06 0 0"/>
      <geometry>
        <cylinder length="0.12" radius="0.015"/>
      </geometry>
      <material name="pusher_red"/>
    </visual>
    <collision>
      <origin rpy="0 1.5708 0" xyz="0.06 0 0"/>
      <geometry>
        <cylinder length="0.12" radius="0.015"/>
      </geometry>
      <surface>
        <friction>
          <ode>
            <mu>1.0</mu>
            <mu2>1.0</mu2>
          </ode>
        </friction>
        <contact>
          <ode>
            <kp>1000000.0</kp>
            <kd>100.0</kd>
          </ode>
        </contact>
      </surface>
    </collision>
    <inertial>
      <origin xyz="0 0 0"/>
      <mass value="0.07"/>
      <inertia ixx="7.875000000000002e-06" ixy="0" ixz="0" iyy="8.793749999999999e-05" iyz="0" izz="8.793749999999999e-05"/>
    </inertial>
  </link>
  <joint name="right_gripper_joint" type="revolute">
    <parent link="lifter_link"/>
    <child link="right_arm_link"/>
    <origin rpy="0 0 0" xyz="0 -0.09 0.05"/>
    <!-- Adjusted z to 0.05m -->
    <axis xyz="0 0 1"/>
    <limit effort="20" lower="-0.6" upper="0.6" velocity="2.0"/>
    <dynamics damping="0.3" friction="0.05"/>
    <mimic joint="left_gripper_joint" multiplier="-1" offset="0"/>
  </joint>
  <!-- Right tip -->
  <link name="right_tip_link">
    <visual>
      <origin rpy="0 1.5708 0" xyz="0.06 0 0"/>
      <geometry>
        <cylinder length="0.12" radius="0.015"/>
      </geometry>
      <material name="pusher_red"/>
    </visual>
    <collision>
      <origin rpy="0 1.5708 0" xyz="0.06 0 0"/>
      <geometry>
        <cylinder length="0.12" radius="0.015"/>
      </geometry>
      <surface>
        <friction>
          <ode>
            <mu>1.0</mu>
            <mu2>1.0</mu2>
          </ode>
        </friction>
        <contact>
          <ode>
            <kp>1000000.0</kp>
            <kd>100.0</kd>
          </ode>
        </contact>
      </surface>
    </collision>
    <inertial>
      <origin xyz="0 0 0"/>
      <mass value="0.07"/>
      <inertia ixx="7.875000000000002e-06" ixy="0" ixz="0" iyy="8.793749999999999e-05" iyz="0" izz="8.793749999999999e-05"/>
    </inertial>
  </link>
  <joint name="right_tip_joint" type="fixed">
    <parent link="right_arm_link"/>
    <child link="right_tip_link"/>
    <origin rpy="0 0 0.349" xyz="0.12 0 0"/>
  </joint>
  <!-- Right tip sphere -->
  <link name="right_sphere_link">
    <visual>
      <origin rpy="0 0 0" xyz="0 0 0"/>
      <geometry>
        <sphere radius="0.02"/>
      </geometry>
      <material name="pusher_red"/>
    </visual>
    <collision name="right_sphere_link_collision">
      <origin rpy="0 0 0" xyz="0 0 0"/>
      <geometry>
        <sphere radius="0.02"/>
      </geometry>
    </collision>
    <inertial>
      <origin xyz="0 0 0"/>
      <mass value="0.02"/>
      <inertia ixx="3.2000000000000003e-06" ixy="0" ixz="0" iyy="3.2000000000000003e-06" iyz="0" izz="3.2000000000000003e-06"/>
    </inertial>
  </link>
  <joint name="right_sphere_joint" type="fixed">
    <parent link="right_tip_link"/>
    <child link="right_sphere_link"/>
    <origin rpy="0 0 0" xyz="0.12 0 0"/>
  </joint>
  <!-- Caster wheel for stability -->
  <link name="caster_link">
    <visual>
      <origin rpy="0 0 0" xyz="0 0 0"/>
      <geometry>
        <sphere radius="0.03"/>
      </geometry>
      <material name="wheel_black"/>
    </visual>
    <collision>
      <origin rpy="0 0 0" xyz="0 0 0"/>
      <geometry>
        <sphere radius="0.03"/>
      </geometry>
    </collision>
    <inertial>
      <origin xyz="0 0 0"/>
      <mass value="0.1"/>
      <inertia ixx="3.6e-05" ixy="0" ixz="0" iyy="3.6e-05" iyz="0" izz="3.6e-05"/>
    </inertial>
  </link>
  <joint name="caster_joint" type="continuous">
    <parent link="base_link"/>
    <child link="caster_link"/>
    <origin rpy="0 0 0" xyz="-0.225 0 -0.04"/>
    <axis xyz="0 0 1"/>
    <dynamics damping="0.1" friction="0.1"/>
  </joint>
  <!-- Back platform for additional payload or sensors -->
  <link name="back_platform_link">
    <visual>
      <origin rpy="0 0 0" xyz="0 0 0"/>
      <geometry>
        <box size="0.45 0.1 0.04"/>
      </geometry>
      <material name="metallic_gray"/>
    </visual>
    <collision>
      <origin rpy="0 0 0" xyz="0 0 0"/>
      <geometry>
        <box size="0.45 0.1 0.04"/>
      </geometry>
    </collision>
    <inertial>
      <origin xyz="0 0 0"/>
      <mass value="0.5"/>
      <inertia ixx="0.001" ixy="0" ixz="0" iyy="0.001" iyz="0" izz="0.001"/>
    </inertial>
  </link>
  <joint name="back_platform_joint" type="fixed">
    <parent link="base_link"/>
    <child link="back_platform_link"/>
    <origin rpy="0 0 0" xyz="-0.225 0 0.04"/>
  </joint>
  <!-- Placeholder for lidar sensor (raised for better visibility) -->
  <link name="lidar_link">
    <visual>
      <origin rpy="0 0 0" xyz="0 0 0"/>
      <geometry>
        <cylinder length="0.05" radius="0.05"/>
      </geometry>
      <material name="metallic_gray"/>
    </visual>
    <collision>
      <origin rpy="0 0 0" xyz="0 0 0"/>
      <geometry>
        <cylinder length="0.05" radius="0.05"/>
      </geometry>
    </collision>
    <inertial>
      <origin xyz="0 0 0"/>
      <mass value="0.2"/>
      <inertia ixx="0.001" ixy="0" ixz="0" iyy="0.001" iyz="0" izz="0.001"/>
    </inertial>
  </link>
  <joint name="lidar_joint" type="fixed">
    <parent link="base_link"/>
    <child link="lidar_link"/>
    <origin rpy="0 0 0" xyz="0 0 0.13"/>
    <!-- Raised by 0.05m -->
  </joint>
  <!-- ================ GAZEBO PLUGINS ================ -->
  <!-- Differential Drive Controller Plugin -->
  <gazebo>
    <plugin filename="libgazebo_ros_diff_drive.so" name="differential_drive_controller">
      <ros>
        <namespace>/</namespace>
      </ros>
      <update_rate>30</update_rate>
      <left_joint>wheel_left_joint</left_joint>
      <right_joint>wheel_right_joint</right_joint>
      <wheel_separation>0.4</wheel_separation>
      <wheel_diameter>0.16</wheel_diameter>
      <max_wheel_torque>30</max_wheel_torque>
      <!-- Increased from 20 -->
      <max_wheel_acceleration>1.0</max_wheel_acceleration>
      <command_topic>cmd_vel/gripper</command_topic>
      <publish_odom>true</publish_odom>
      <publish_odom_tf>true</publish_odom_tf>
      <odometry_topic>odom</odometry_topic>
      <odometry_frame>odom</odometry_frame>
      <robot_base_frame>base_link</robot_base_frame>
    </plugin>
  </gazebo>
  <!-- Joint State Publisher Plugin -->
  <gazebo>
    <plugin filename="libgazebo_ros_joint_state_publisher.so" name="gazebo_ros_joint_state_publisher">
      <ros>
        <namespace>/</namespace>
      </ros>
      <update_rate>50</update_rate>
      <joint_name>wheel_left_joint</joint_name>
      <joint_name>wheel_right_joint</joint_name>
      <joint_name>front_lifter_joint</joint_name>
      <joint_name>left_gripper_joint</joint_name>
      <joint_name>right_gripper_joint</joint_name>
      <joint_name>caster_joint</joint_name>
    </plugin>
  </gazebo>
  <!-- Laser Scanner Plugin -->
  <gazebo reference="lidar_link">
    <sensor name="laser_scanner" type="ray">
      <pose>0 0 0 0 0 0</pose>
      <visualize>false</visualize>
      <update_rate>40</update_rate>
      <ray>
        <scan>
          <horizontal>
            <samples>720</samples>
            <resolution>1</resolution>
            <min_angle>-1.570796</min_angle>
            <max_angle>1.570796</max_angle>
          </horizontal>
        </scan>
        <range>
          <min>0.10</min>
          <max>30.0</max>
          <resolution>0.01</resolution>
        </range>
        <noise>
          <type>gaussian</type>
          <mean>0.0</mean>
          <stddev>0.01</stddev>
        </noise>
      </ray>
      <plugin filename="libgazebo_ros_ray_sensor.so" name="gazebo_ros_laser">
        <ros>
          <namespace>/</namespace>
        </ros>
        <output_type>sensor_msgs/LaserScan</output_type>
        <topicName>scan</topicName>
        <frameName>lidar_link</frameName>
      </plugin>
    </sensor>
  </gazebo>
  <!-- Joint Position Controllers for Gripper and Lifter -->
  <gazebo>
    <plugin filename="libgazebo_ros2_control.so" name="gazebo_ros2_control">
      <parameters>/home/ke/Desktop/study/ROS/5_ImproveInteraction/ws/install/gpu_slam_bot/share/gpu_slam_bot/config/controllers.yaml</parameters>
    </plugin>
  </gazebo>
  <!-- Gazebo material properties -->
  <gazebo reference="base_link">
    <material>Gazebo/Grey</material>
  </gazebo>
  <gazebo reference="wheel_left">
    <material>Gazebo/Black</material>
    <mu1>1.0</mu1>
    <!-- Increased from 0.8 -->
    <mu2>1.0</mu2>
    <!-- Increased from 0.8 -->
  </gazebo>
  <gazebo reference="wheel_right">
    <material>Gazebo/Black</material>
    <mu1>1.0</mu1>
    <!-- Increased from 0.8 -->
    <mu2>1.0</mu2>
    <!-- Increased from 0.8 -->
  </gazebo>
  <gazebo reference="caster_link">
    <material>Gazebo/Black</material>
    <mu1>0.0</mu1>
    <mu2>0.0</mu2>
  </gazebo>
  <gazebo reference="lifter_link">
    <material>Gazebo/Grey</material>
  </gazebo>
  <gazebo reference="left_arm_link">
    <material>Gazebo/Red</material>
  </gazebo>
  <gazebo reference="right_arm_link">
    <material>Gazebo/Red</material>
  </gazebo>
  <!-- ===================== TRANSMISSIONS ===================== -->
  <!-- Left Gripper Transmission -->
  <transmission name="left_gripper_trans">
    <type>transmission_interface/SimpleTransmission</type>
    <joint name="left_gripper_joint">
      <hardwareInterface>PositionJointInterface</hardwareInterface>
    </joint>
    <actuator name="left_gripper_motor">
      <hardwareInterface>PositionJointInterface</hardwareInterface>
      <mechanicalReduction>1</mechanicalReduction>
    </actuator>
  </transmission>
  <!-- Right Gripper Transmission (mimics left) -->
  <transmission name="right_gripper_trans">
    <type>transmission_interface/SimpleTransmission</type>
    <joint name="right_gripper_joint">
      <hardwareInterface>PositionJointInterface</hardwareInterface>
    </joint>
    <actuator name="right_gripper_motor">
      <hardwareInterface>PositionJointInterface</hardwareInterface>
      <mechanicalReduction>1</mechanicalReduction>
    </actuator>
  </transmission>
  <!-- Front Lifter Transmission -->
  <transmission name="lifter_trans">
    <type>transmission_interface/SimpleTransmission</type>
    <joint name="front_lifter_joint">
      <hardwareInterface>PositionJointInterface</hardwareInterface>
    </joint>
    <actuator name="lifter_motor">
      <hardwareInterface>PositionJointInterface</hardwareInterface>
      <mechanicalReduction>1</mechanicalReduction>
    </actuator>
  </transmission>
</robot>
