<?xml version="1.0" ?>
<!-- =================================================================================== -->
<!-- |    This document was autogenerated by xacro from src/gpu_slam_bot/urdf/gpu_slam_bot.urdf.xacro | -->
<!-- |    EDITING THIS FILE BY HAND IS NOT RECOMMENDED                                 | -->
<!-- =================================================================================== -->
<robot name="gpu_slam_bot">
  <!-- Materials -->
  <material name="metallic_gray">
    <color rgba="0.7 0.7 0.75 1"/>
  </material>
  <material name="wheel_black">
    <color rgba="0 0 0 1"/>
  </material>
  <material name="stripe_green">
    <color rgba="0 1 0 1"/>
  </material>
  <material name="pusher_red">
    <color rgba="1 0 0 1"/>
  </material>
  <!-- Base link -->
  <link name="base_link">
    <visual>
      <origin rpy="0 0 0" xyz="0 0 0"/>
      <geometry>
        <box size="0.45 0.3 0.08"/>
      </geometry>
      <material name="metallic_gray"/>
    </visual>
    <collision>
      <origin rpy="0 0 0" xyz="0 0 0"/>
      <geometry>
        <box size="0.45 0.3 0.08"/>
      </geometry>
    </collision>
    <inertial>
      <origin xyz="0 0 0"/>
      <mass value="3.0"/>
      <inertia ixx="0.0241" ixy="0" ixz="0" iyy="0.052225" iyz="0" izz="0.073125"/>
    </inertial>
  </link>
  <!-- Lidar -->
  <link name="lidar_link">
    <visual>
      <origin rpy="0 0 0" xyz="0 0 0.03"/>
      <geometry>
        <cylinder length="0.06" radius="0.055"/>
      </geometry>
      <material name="metallic_gray"/>
    </visual>
    <collision>
      <origin rpy="0 0 0" xyz="0 0 0.03"/>
      <geometry>
        <cylinder length="0.06" radius="0.055"/>
      </geometry>
    </collision>
    <inertial>
      <origin xyz="0 0 0.03"/>
      <mass value="0.2"/>
      <inertia ixx="0.0004" ixy="0" ixz="0" iyy="0.0004" iyz="0" izz="0.0003"/>
    </inertial>
  </link>
  <joint name="lidar_joint" type="fixed">
    <parent link="base_link"/>
    <child link="lidar_link"/>
    <origin rpy="0 0 0" xyz="0 0 0.07"/>
  </joint>
  <!-- Left Wheel - FIXED orientation and positioning -->
  <link name="wheel_left">
    <visual>
      <origin rpy="1.5708 0 0" xyz="0 0 0"/>
      <geometry>
        <cylinder length="0.06" radius="0.08"/>
      </geometry>
      <material name="wheel_black"/>
    </visual>
    <collision>
      <origin rpy="1.5708 0 0" xyz="0 0 0"/>
      <geometry>
        <cylinder length="0.06" radius="0.08"/>
      </geometry>
    </collision>
    <inertial>
      <origin xyz="0 0 0"/>
      <mass value="1.5"/>
      <inertia ixx="0.0028499999999999997" ixy="0" ixz="0" iyy="0.0048" iyz="0" izz="0.0028499999999999997"/>
    </inertial>
  </link>
  <!-- Right Wheel - FIXED orientation and positioning -->
  <link name="wheel_right">
    <visual>
      <origin rpy="1.5708 0 0" xyz="0 0 0"/>
      <geometry>
        <cylinder length="0.06" radius="0.08"/>
      </geometry>
      <material name="wheel_black"/>
    </visual>
    <collision>
      <origin rpy="1.5708 0 0" xyz="0 0 0"/>
      <geometry>
        <cylinder length="0.06" radius="0.08"/>
      </geometry>
    </collision>
    <inertial>
      <origin xyz="0 0 0"/>
      <mass value="1.5"/>
      <inertia ixx="0.0028499999999999997" ixy="0" ixz="0" iyy="0.0048" iyz="0" izz="0.0028499999999999997"/>
    </inertial>
  </link>
  <!-- Wheel joints - FIXED positioning and rotation axis -->
  <joint name="wheel_left_joint" type="continuous">
    <parent link="base_link"/>
    <child link="wheel_left"/>
    <origin rpy="0 0 0" xyz="0 0.175 -0.08"/>
    <axis xyz="0 1 0"/>
    <dynamics damping="0.1" friction="0.1"/>
  </joint>
  <joint name="wheel_right_joint" type="continuous">
    <parent link="base_link"/>
    <child link="wheel_right"/>
    <origin rpy="0 0 0" xyz="0 -0.175 -0.08"/>
    <axis xyz="0 1 0"/>
    <dynamics damping="0.1" friction="0.1"/>
  </joint>
  <!-- Caster - FIXED positioning -->
  <link name="caster_link">
    <visual>
      <origin rpy="0 0 0" xyz="0 0 0"/>
      <geometry>
        <sphere radius="0.03"/>
      </geometry>
      <material name="metallic_gray"/>
    </visual>
    <collision>
      <origin rpy="0 0 0" xyz="0 0 0"/>
      <geometry>
        <sphere radius="0.03"/>
      </geometry>
    </collision>
    <inertial>
      <origin xyz="0 0 0"/>
      <mass value="0.1"/>
      <inertia ixx="3.6e-05" ixy="0" ixz="0" iyy="3.6e-05" iyz="0" izz="3.6e-05"/>
    </inertial>
  </link>
  <joint name="caster_joint" type="fixed">
    <parent link="base_link"/>
    <child link="caster_link"/>
    <origin rpy="0 0 0" xyz="-0.175 0 -0.055"/>
  </joint>
  <!-- Front pusher -->
  <link name="front_pusher_link">
    <visual>
      <origin rpy="0 0 0" xyz="0 0 0"/>
      <geometry>
        <box size="0.02 0.20 0.06"/>
      </geometry>
      <material name="pusher_red"/>
    </visual>
    <collision>
      <origin rpy="0 0 0" xyz="0 0 0"/>
      <geometry>
        <box size="0.02 0.20 0.06"/>
      </geometry>
    </collision>
    <inertial>
      <origin xyz="0 0 0"/>
      <mass value="0.1"/>
      <inertia ixx="0.0003633333333333334" ixy="0" ixz="0" iyy="3.3333333333333335e-05" iyz="0" izz="0.0003366666666666667"/>
    </inertial>
  </link>
  <joint name="front_lifter_joint" type="prismatic">
    <parent link="base_link"/>
    <child link="front_pusher_link"/>
    <origin rpy="0 0 0" xyz="0.23500000000000001 0 -0.04"/>
    <axis xyz="0 0 1"/>
    <limit effort="10" lower="0.0" upper="0.25" velocity="0.1"/>
    <dynamics damping="2.0" friction="0.5"/>
  </joint>
  <!-- Gazebo diff_drive plugin -->
  <gazebo>
    <plugin filename="libgazebo_ros_diff_drive.so" name="diff_drive">
      <ros>
        <namespace>/</namespace>
      </ros>
      <update_rate>100</update_rate>
      <left_joint>wheel_left_joint</left_joint>
      <right_joint>wheel_right_joint</right_joint>
      <wheel_separation>0.35</wheel_separation>
      <wheel_diameter>0.16</wheel_diameter>
      <max_wheel_torque>50.0</max_wheel_torque>
      <max_wheel_acceleration>10.0</max_wheel_acceleration>
      <command_topic>cmd_vel</command_topic>
      <odometry_topic>odom</odometry_topic>
      <odometry_frame>odom</odometry_frame>
      <robot_base_frame>base_link</robot_base_frame>
      <publish_odom>true</publish_odom>
      <publish_wheel_tf>true</publish_wheel_tf>
      <publish_tf>true</publish_tf>
      <publish_odom_tf>true</publish_odom_tf>
    </plugin>
  </gazebo>
  <!-- Gazebo plugin for pusher control -->
  <gazebo>
    <plugin filename="libgazebo_ros_joint_pose_trajectory.so" name="lifter_position_controller">
      <ros>
        <namespace>/</namespace>
      </ros>
      <joint_name>front_lifter_joint</joint_name>
      <topic_name>front_lifter_cmd</topic_name>
    </plugin>
  </gazebo>
  <!-- Gazebo materials and physics -->
  <gazebo reference="base_link">
    <material>Gazebo/Grey</material>
  </gazebo>
  <gazebo reference="lidar_link">
    <material>Gazebo/Grey</material>
  </gazebo>
  <gazebo reference="front_pusher_link">
    <material>Gazebo/Red</material>
  </gazebo>
  <!-- Wheel physics properties -->
  <gazebo reference="wheel_left">
    <material>Gazebo/Black</material>
    <surface>
      <friction>
        <ode>
          <mu>1.0</mu>
          <mu2>1.0</mu2>
          <fdir1>1 0 0</fdir1>
        </ode>
      </friction>
    </surface>
  </gazebo>
  <gazebo reference="wheel_right">
    <material>Gazebo/Black</material>
    <surface>
      <friction>
        <ode>
          <mu>1.0</mu>
          <mu2>1.0</mu2>
          <fdir1>1 0 0</fdir1>
        </ode>
      </friction>
    </surface>
  </gazebo>
  <!-- Caster physics -->
  <gazebo reference="caster_link">
    <material>Gazebo/Grey</material>
    <surface>
      <friction>
        <ode>
          <mu>0.01</mu>
          <mu2>0.01</mu2>
        </ode>
      </friction>
    </surface>
  </gazebo>
</robot>
